<?xml version="1.0" encoding="UTF-8"?>
<!-- Generated by org.testng.reporters.JUnitReportReporter -->
<testsuite hostname="LAPTOP-VCQHI407" failures="1" tests="16" name="com.nkxgen.spring.jdbc.Test.LoanControllerTest" time="1.315" errors="3" timestamp="2023-07-02T11:17:41 IST" skipped="0">
  <testcase classname="com.nkxgen.spring.jdbc.Test.LoanControllerTest" name="testDeleteLoanApplication_Success" time="0.008"/>
  <testcase classname="com.nkxgen.spring.jdbc.Test.LoanControllerTest" name="testGetLoanApplicationById_Success" time="0.005"/>
  <testcase classname="com.nkxgen.spring.jdbc.Test.LoanControllerTest" name="testGetLoanAccounts_Success" time="0.006"/>
  <testcase classname="com.nkxgen.spring.jdbc.Test.LoanControllerTest" name="testLoanNewApplicationForm" time="0.003"/>
  <testcase classname="com.nkxgen.spring.jdbc.Test.LoanControllerTest" name="testRedirectForm" time="0.005"/>
  <testcase classname="com.nkxgen.spring.jdbc.Test.LoanControllerTest" name="testGetLoanApplication_Success" time="0.005"/>
  <testcase classname="com.nkxgen.spring.jdbc.Test.LoanControllerTest" name="testUpdateLoanApplication_Success" time="0.005"/>
  <testcase classname="com.nkxgen.spring.jdbc.Test.LoanControllerTest" name="testApproveLoanApplication_Exception" time="1.213">
    <error message="
Checked exception is invalid for this method!
Invalid: java.lang.Exception" type="org.mockito.exceptions.base.MockitoException">
      <![CDATA[org.mockito.exceptions.base.MockitoException: 
Checked exception is invalid for this method!
Invalid: java.lang.Exception
at com.nkxgen.spring.jdbc.Test.LoanControllerTest.testApproveLoanApplication_Exception(LoanControllerTest.java:268)
at java.base/jdk.internal.reflect.NativeMethodAccessorImpl.invoke0(Native Method)
at java.base/jdk.internal.reflect.NativeMethodAccessorImpl.invoke(NativeMethodAccessorImpl.java:77)
at java.base/jdk.internal.reflect.DelegatingMethodAccessorImpl.invoke(DelegatingMethodAccessorImpl.java:43)
at java.base/java.lang.reflect.Method.invoke(Method.java:568)
at org.testng.internal.invokers.MethodInvocationHelper.invokeMethod(MethodInvocationHelper.java:139)
at org.testng.internal.invokers.TestInvoker.invokeMethod(TestInvoker.java:664)
at org.testng.internal.invokers.TestInvoker.invokeTestMethod(TestInvoker.java:227)
at org.testng.internal.invokers.MethodRunner.runInSequence(MethodRunner.java:50)
at org.testng.internal.invokers.TestInvoker$MethodInvocationAgent.invoke(TestInvoker.java:957)
at org.testng.internal.invokers.TestInvoker.invokeTestMethods(TestInvoker.java:200)
at org.testng.internal.invokers.TestMethodWorker.invokeTestMethods(TestMethodWorker.java:148)
at org.testng.internal.invokers.TestMethodWorker.run(TestMethodWorker.java:128)
at java.base/java.util.ArrayList.forEach(ArrayList.java:1511)
at org.testng.TestRunner.privateRun(TestRunner.java:848)
at org.testng.TestRunner.run(TestRunner.java:621)
at org.testng.SuiteRunner.runTest(SuiteRunner.java:443)
at org.testng.SuiteRunner.runSequentially(SuiteRunner.java:437)
at org.testng.SuiteRunner.privateRun(SuiteRunner.java:397)
at org.testng.SuiteRunner.run(SuiteRunner.java:336)
at org.testng.SuiteRunnerWorker.runSuite(SuiteRunnerWorker.java:52)
at org.testng.SuiteRunnerWorker.run(SuiteRunnerWorker.java:95)
at org.testng.TestNG.runSuitesSequentially(TestNG.java:1280)
at org.testng.TestNG.runSuitesLocally(TestNG.java:1200)
at org.testng.TestNG.runSuites(TestNG.java:1114)
at org.testng.TestNG.run(TestNG.java:1082)
at org.testng.remote.AbstractRemoteTestNG.run(AbstractRemoteTestNG.java:115)
at org.testng.remote.RemoteTestNG.initAndRun(RemoteTestNG.java:251)
at org.testng.remote.RemoteTestNG.main(RemoteTestNG.java:77)
]]>
    </error>
  </testcase> <!-- testApproveLoanApplication_Exception -->
  <testcase classname="com.nkxgen.spring.jdbc.Test.LoanControllerTest" name="testUpdateLoanApplication_Exception" time="0.006">
    <error message="
Checked exception is invalid for this method!
Invalid: java.lang.Exception" type="org.mockito.exceptions.base.MockitoException">
      <![CDATA[org.mockito.exceptions.base.MockitoException: 
Checked exception is invalid for this method!
Invalid: java.lang.Exception
at com.nkxgen.spring.jdbc.Test.LoanControllerTest.testUpdateLoanApplication_Exception(LoanControllerTest.java:176)
at java.base/jdk.internal.reflect.NativeMethodAccessorImpl.invoke0(Native Method)
at java.base/jdk.internal.reflect.NativeMethodAccessorImpl.invoke(NativeMethodAccessorImpl.java:77)
at java.base/jdk.internal.reflect.DelegatingMethodAccessorImpl.invoke(DelegatingMethodAccessorImpl.java:43)
at java.base/java.lang.reflect.Method.invoke(Method.java:568)
at org.testng.internal.invokers.MethodInvocationHelper.invokeMethod(MethodInvocationHelper.java:139)
at org.testng.internal.invokers.TestInvoker.invokeMethod(TestInvoker.java:664)
at org.testng.internal.invokers.TestInvoker.invokeTestMethod(TestInvoker.java:227)
at org.testng.internal.invokers.MethodRunner.runInSequence(MethodRunner.java:50)
at org.testng.internal.invokers.TestInvoker$MethodInvocationAgent.invoke(TestInvoker.java:957)
at org.testng.internal.invokers.TestInvoker.invokeTestMethods(TestInvoker.java:200)
at org.testng.internal.invokers.TestMethodWorker.invokeTestMethods(TestMethodWorker.java:148)
at org.testng.internal.invokers.TestMethodWorker.run(TestMethodWorker.java:128)
at java.base/java.util.ArrayList.forEach(ArrayList.java:1511)
at org.testng.TestRunner.privateRun(TestRunner.java:848)
at org.testng.TestRunner.run(TestRunner.java:621)
at org.testng.SuiteRunner.runTest(SuiteRunner.java:443)
at org.testng.SuiteRunner.runSequentially(SuiteRunner.java:437)
at org.testng.SuiteRunner.privateRun(SuiteRunner.java:397)
at org.testng.SuiteRunner.run(SuiteRunner.java:336)
at org.testng.SuiteRunnerWorker.runSuite(SuiteRunnerWorker.java:52)
at org.testng.SuiteRunnerWorker.run(SuiteRunnerWorker.java:95)
at org.testng.TestNG.runSuitesSequentially(TestNG.java:1280)
at org.testng.TestNG.runSuitesLocally(TestNG.java:1200)
at org.testng.TestNG.runSuites(TestNG.java:1114)
at org.testng.TestNG.run(TestNG.java:1082)
at org.testng.remote.AbstractRemoteTestNG.run(AbstractRemoteTestNG.java:115)
at org.testng.remote.RemoteTestNG.initAndRun(RemoteTestNG.java:251)
at org.testng.remote.RemoteTestNG.main(RemoteTestNG.java:77)
]]>
    </error>
  </testcase> <!-- testUpdateLoanApplication_Exception -->
  <testcase classname="com.nkxgen.spring.jdbc.Test.LoanControllerTest" name="testDeleteLoanApplication_Exception" time="0.002">
    <error message="
Checked exception is invalid for this method!
Invalid: java.lang.Exception" type="org.mockito.exceptions.base.MockitoException">
      <![CDATA[org.mockito.exceptions.base.MockitoException: 
Checked exception is invalid for this method!
Invalid: java.lang.Exception
at com.nkxgen.spring.jdbc.Test.LoanControllerTest.testDeleteLoanApplication_Exception(LoanControllerTest.java:231)
at java.base/jdk.internal.reflect.NativeMethodAccessorImpl.invoke0(Native Method)
at java.base/jdk.internal.reflect.NativeMethodAccessorImpl.invoke(NativeMethodAccessorImpl.java:77)
at java.base/jdk.internal.reflect.DelegatingMethodAccessorImpl.invoke(DelegatingMethodAccessorImpl.java:43)
at java.base/java.lang.reflect.Method.invoke(Method.java:568)
at org.testng.internal.invokers.MethodInvocationHelper.invokeMethod(MethodInvocationHelper.java:139)
at org.testng.internal.invokers.TestInvoker.invokeMethod(TestInvoker.java:664)
at org.testng.internal.invokers.TestInvoker.invokeTestMethod(TestInvoker.java:227)
at org.testng.internal.invokers.MethodRunner.runInSequence(MethodRunner.java:50)
at org.testng.internal.invokers.TestInvoker$MethodInvocationAgent.invoke(TestInvoker.java:957)
at org.testng.internal.invokers.TestInvoker.invokeTestMethods(TestInvoker.java:200)
at org.testng.internal.invokers.TestMethodWorker.invokeTestMethods(TestMethodWorker.java:148)
at org.testng.internal.invokers.TestMethodWorker.run(TestMethodWorker.java:128)
at java.base/java.util.ArrayList.forEach(ArrayList.java:1511)
at org.testng.TestRunner.privateRun(TestRunner.java:848)
at org.testng.TestRunner.run(TestRunner.java:621)
at org.testng.SuiteRunner.runTest(SuiteRunner.java:443)
at org.testng.SuiteRunner.runSequentially(SuiteRunner.java:437)
at org.testng.SuiteRunner.privateRun(SuiteRunner.java:397)
at org.testng.SuiteRunner.run(SuiteRunner.java:336)
at org.testng.SuiteRunnerWorker.runSuite(SuiteRunnerWorker.java:52)
at org.testng.SuiteRunnerWorker.run(SuiteRunnerWorker.java:95)
at org.testng.TestNG.runSuitesSequentially(TestNG.java:1280)
at org.testng.TestNG.runSuitesLocally(TestNG.java:1200)
at org.testng.TestNG.runSuites(TestNG.java:1114)
at org.testng.TestNG.run(TestNG.java:1082)
at org.testng.remote.AbstractRemoteTestNG.run(AbstractRemoteTestNG.java:115)
at org.testng.remote.RemoteTestNG.initAndRun(RemoteTestNG.java:251)
at org.testng.remote.RemoteTestNG.main(RemoteTestNG.java:77)
]]>
    </error>
  </testcase> <!-- testDeleteLoanApplication_Exception -->
  <testcase classname="com.nkxgen.spring.jdbc.Test.LoanControllerTest" name="testNewLoanApplication_Success" time="0.008"/>
  <testcase classname="com.nkxgen.spring.jdbc.Test.LoanControllerTest" name="testGetLoanApplicationById_ApplicationNotFound" time="0.004"/>
  <testcase classname="com.nkxgen.spring.jdbc.Test.LoanControllerTest" name="testNewLoanApplication_Exception" time="0.009"/>
  <testcase classname="com.nkxgen.spring.jdbc.Test.LoanControllerTest" name="testGetAccountById_Success" time="0.004"/>
  <testcase classname="com.nkxgen.spring.jdbc.Test.LoanControllerTest" name="testApproveLoanApplication_Success" time="0.024">
    <failure message="
Argument(s) are different! Wanted:
loanApplicationDao.getLoanApplicationByid(
    (Integer) 1
);
-&gt; at com.nkxgen.spring.jdbc.Test.LoanControllerTest.testApproveLoanApplication_Success(LoanControllerTest.java:253)
Actual invocation has different arguments:
loanApplicationDao.getLoanApplicationByid(
    (Long) 1L
);
-&gt; at com.nkxgen.spring.jdbc.controller.LoanController.approveLoanApplication(LoanController.java:196)
" type="org.mockito.exceptions.verification.ArgumentsAreDifferent">
      <![CDATA[Argument(s) are different! Wanted:
loanApplicationDao.getLoanApplicationByid(
    (Integer) 1
);
-> at com.nkxgen.spring.jdbc.Test.LoanControllerTest.testApproveLoanApplication_Success(LoanControllerTest.java:253)
Actual invocation has different arguments:
loanApplicationDao.getLoanApplicationByid(
    (Long) 1L
);
-> at com.nkxgen.spring.jdbc.controller.LoanController.approveLoanApplication(LoanController.java:196)

at com.nkxgen.spring.jdbc.Test.LoanControllerTest.testApproveLoanApplication_Success(LoanControllerTest.java:253)
at java.base/jdk.internal.reflect.NativeMethodAccessorImpl.invoke0(Native Method)
at java.base/jdk.internal.reflect.NativeMethodAccessorImpl.invoke(NativeMethodAccessorImpl.java:77)
at java.base/jdk.internal.reflect.DelegatingMethodAccessorImpl.invoke(DelegatingMethodAccessorImpl.java:43)
at java.base/java.lang.reflect.Method.invoke(Method.java:568)
at org.testng.internal.invokers.MethodInvocationHelper.invokeMethod(MethodInvocationHelper.java:139)
at org.testng.internal.invokers.TestInvoker.invokeMethod(TestInvoker.java:664)
at org.testng.internal.invokers.TestInvoker.invokeTestMethod(TestInvoker.java:227)
at org.testng.internal.invokers.MethodRunner.runInSequence(MethodRunner.java:50)
at org.testng.internal.invokers.TestInvoker$MethodInvocationAgent.invoke(TestInvoker.java:957)
at org.testng.internal.invokers.TestInvoker.invokeTestMethods(TestInvoker.java:200)
at org.testng.internal.invokers.TestMethodWorker.invokeTestMethods(TestMethodWorker.java:148)
at org.testng.internal.invokers.TestMethodWorker.run(TestMethodWorker.java:128)
at java.base/java.util.ArrayList.forEach(ArrayList.java:1511)
at org.testng.TestRunner.privateRun(TestRunner.java:848)
at org.testng.TestRunner.run(TestRunner.java:621)
at org.testng.SuiteRunner.runTest(SuiteRunner.java:443)
at org.testng.SuiteRunner.runSequentially(SuiteRunner.java:437)
at org.testng.SuiteRunner.privateRun(SuiteRunner.java:397)
at org.testng.SuiteRunner.run(SuiteRunner.java:336)
at org.testng.SuiteRunnerWorker.runSuite(SuiteRunnerWorker.java:52)
at org.testng.SuiteRunnerWorker.run(SuiteRunnerWorker.java:95)
at org.testng.TestNG.runSuitesSequentially(TestNG.java:1280)
at org.testng.TestNG.runSuitesLocally(TestNG.java:1200)
at org.testng.TestNG.runSuites(TestNG.java:1114)
at org.testng.TestNG.run(TestNG.java:1082)
at org.testng.remote.AbstractRemoteTestNG.run(AbstractRemoteTestNG.java:115)
at org.testng.remote.RemoteTestNG.initAndRun(RemoteTestNG.java:251)
at org.testng.remote.RemoteTestNG.main(RemoteTestNG.java:77)
]]>
    </failure>
  </testcase> <!-- testApproveLoanApplication_Success -->
  <testcase classname="com.nkxgen.spring.jdbc.Test.LoanControllerTest" name="testGetAccountById_AccountNotFound" time="0.008"/>
</testsuite> <!-- com.nkxgen.spring.jdbc.Test.LoanControllerTest -->
